[2024-07-25T23:43:23.881+0000] {taskinstance.py:1979} INFO - Dependencies all met for dep_context=non-requeueable deps ti=<TaskInstance: openweathermap.send_email manual__2024-07-25T23:43:15.698251+00:00 [queued]>
[2024-07-25T23:43:23.888+0000] {taskinstance.py:1979} INFO - Dependencies all met for dep_context=requeueable deps ti=<TaskInstance: openweathermap.send_email manual__2024-07-25T23:43:15.698251+00:00 [queued]>
[2024-07-25T23:43:23.888+0000] {taskinstance.py:2193} INFO - Starting attempt 1 of 2
[2024-07-25T23:43:23.899+0000] {taskinstance.py:2217} INFO - Executing <Task(_PythonDecoratedOperator): send_email> on 2024-07-25 23:43:15.698251+00:00
[2024-07-25T23:43:23.905+0000] {standard_task_runner.py:60} INFO - Started process 1431 to run task
[2024-07-25T23:43:23.907+0000] {standard_task_runner.py:87} INFO - Running: ['***', 'tasks', 'run', 'openweathermap', 'send_email', 'manual__2024-07-25T23:43:15.698251+00:00', '--job-id', '90', '--raw', '--subdir', 'DAGS_FOLDER/weather_dag.py', '--cfg-path', '/tmp/tmp10tqphaf']
[2024-07-25T23:43:23.909+0000] {standard_task_runner.py:88} INFO - Job 90: Subtask send_email
[2024-07-25T23:43:23.945+0000] {task_command.py:423} INFO - Running <TaskInstance: openweathermap.send_email manual__2024-07-25T23:43:15.698251+00:00 [running]> on host 528d4c21eff6
[2024-07-25T23:43:24.009+0000] {taskinstance.py:2513} INFO - Exporting env vars: AIRFLOW_CTX_DAG_OWNER='snowglobe' AIRFLOW_CTX_DAG_ID='openweathermap' AIRFLOW_CTX_TASK_ID='send_email' AIRFLOW_CTX_EXECUTION_DATE='2024-07-25T23:43:15.698251+00:00' AIRFLOW_CTX_TRY_NUMBER='1' AIRFLOW_CTX_DAG_RUN_ID='manual__2024-07-25T23:43:15.698251+00:00'
[2024-07-25T23:43:24.018+0000] {warnings.py:109} WARNING - /home/***/.local/lib/python3.8/site-packages/***/utils/email.py:154: RemovedInAirflow3Warning: Fetching SMTP credentials from configuration variables will be deprecated in a future release. Please set credentials using a connection instead.
  send_mime_email(e_from=mail_from, e_to=recipients, mime_msg=msg, conn_id=conn_id, dryrun=dryrun)

[2024-07-25T23:43:24.018+0000] {email.py:270} INFO - Email alerting: attempt 1
[2024-07-25T23:43:24.328+0000] {taskinstance.py:2731} ERROR - Task failed with exception
Traceback (most recent call last):
  File "/home/airflow/.local/lib/python3.8/site-packages/airflow/models/taskinstance.py", line 444, in _execute_task
    result = _execute_callable(context=context, **execute_callable_kwargs)
  File "/home/airflow/.local/lib/python3.8/site-packages/airflow/models/taskinstance.py", line 414, in _execute_callable
    return execute_callable(context=context, **execute_callable_kwargs)
  File "/home/airflow/.local/lib/python3.8/site-packages/airflow/decorators/base.py", line 241, in execute
    return_value = super().execute(context)
  File "/home/airflow/.local/lib/python3.8/site-packages/airflow/operators/python.py", line 200, in execute
    return_value = self.execute_callable()
  File "/home/airflow/.local/lib/python3.8/site-packages/airflow/operators/python.py", line 217, in execute_callable
    return self.python_callable(*self.op_args, **self.op_kwargs)
  File "/opt/airflow/dags/weather_dag.py", line 86, in send_email
    email.execute(context=None)
  File "/home/airflow/.local/lib/python3.8/site-packages/airflow/operators/email.py", line 79, in execute
    send_email(
  File "/home/airflow/.local/lib/python3.8/site-packages/airflow/utils/email.py", line 80, in send_email
    return backend(
  File "/home/airflow/.local/lib/python3.8/site-packages/airflow/utils/email.py", line 154, in send_email_smtp
    send_mime_email(e_from=mail_from, e_to=recipients, mime_msg=msg, conn_id=conn_id, dryrun=dryrun)
  File "/home/airflow/.local/lib/python3.8/site-packages/airflow/utils/email.py", line 280, in send_mime_email
    smtp_conn.login(smtp_user, smtp_password)
  File "/usr/local/lib/python3.8/smtplib.py", line 748, in login
    raise last_exception
  File "/usr/local/lib/python3.8/smtplib.py", line 737, in login
    (code, resp) = self.auth(
  File "/usr/local/lib/python3.8/smtplib.py", line 660, in auth
    raise SMTPAuthenticationError(code, resp)
smtplib.SMTPAuthenticationError: (534, b'5.7.9 Application-specific password required. For more information, go to\n5.7.9  https://support.google.com/mail/?p=InvalidSecondFactor d9443c01a7336-1fed7cf6861sm19808195ad.86 - gsmtp')
[2024-07-25T23:43:24.335+0000] {taskinstance.py:1149} INFO - Marking task as UP_FOR_RETRY. dag_id=openweathermap, task_id=send_email, execution_date=20240725T234315, start_date=20240725T234323, end_date=20240725T234324
[2024-07-25T23:43:24.344+0000] {standard_task_runner.py:107} ERROR - Failed to execute job 90 for task send_email ((534, b'5.7.9 Application-specific password required. For more information, go to\n5.7.9  https://support.google.com/mail/?p=InvalidSecondFactor d9443c01a7336-1fed7cf6861sm19808195ad.86 - gsmtp'); 1431)
[2024-07-25T23:43:24.361+0000] {local_task_job_runner.py:234} INFO - Task exited with return code 1
[2024-07-25T23:43:24.374+0000] {taskinstance.py:3312} INFO - 0 downstream tasks scheduled from follow-on schedule check
