[2024-07-24T01:17:14.813+0000] {taskinstance.py:1979} INFO - Dependencies all met for dep_context=non-requeueable deps ti=<TaskInstance: openweathermap.weather_fetch_honolulu manual__2024-07-24T01:17:12.470445+00:00 [queued]>
[2024-07-24T01:17:14.818+0000] {taskinstance.py:1979} INFO - Dependencies all met for dep_context=requeueable deps ti=<TaskInstance: openweathermap.weather_fetch_honolulu manual__2024-07-24T01:17:12.470445+00:00 [queued]>
[2024-07-24T01:17:14.819+0000] {taskinstance.py:2193} INFO - Starting attempt 1 of 2
[2024-07-24T01:17:14.829+0000] {taskinstance.py:2217} INFO - Executing <Task(HttpOperator): weather_fetch_honolulu> on 2024-07-24 01:17:12.470445+00:00
[2024-07-24T01:17:14.834+0000] {standard_task_runner.py:60} INFO - Started process 80 to run task
[2024-07-24T01:17:14.835+0000] {standard_task_runner.py:87} INFO - Running: ['***', 'tasks', 'run', 'openweathermap', 'weather_fetch_honolulu', 'manual__2024-07-24T01:17:12.470445+00:00', '--job-id', '14', '--raw', '--subdir', 'DAGS_FOLDER/weather_dag.py', '--cfg-path', '/tmp/tmp1icryfud']
[2024-07-24T01:17:14.837+0000] {standard_task_runner.py:88} INFO - Job 14: Subtask weather_fetch_honolulu
[2024-07-24T01:17:14.870+0000] {task_command.py:423} INFO - Running <TaskInstance: openweathermap.weather_fetch_honolulu manual__2024-07-24T01:17:12.470445+00:00 [running]> on host 6a99bf73a015
[2024-07-24T01:17:14.930+0000] {taskinstance.py:2513} INFO - Exporting env vars: AIRFLOW_CTX_DAG_OWNER='snowglobe' AIRFLOW_CTX_DAG_ID='openweathermap' AIRFLOW_CTX_TASK_ID='weather_fetch_honolulu' AIRFLOW_CTX_EXECUTION_DATE='2024-07-24T01:17:12.470445+00:00' AIRFLOW_CTX_TRY_NUMBER='1' AIRFLOW_CTX_DAG_RUN_ID='manual__2024-07-24T01:17:12.470445+00:00'
[2024-07-24T01:17:14.932+0000] {http.py:169} INFO - Calling HTTP method
[2024-07-24T01:17:14.943+0000] {taskinstance.py:2731} ERROR - Task failed with exception
Traceback (most recent call last):
  File "/home/airflow/.local/lib/python3.8/site-packages/airflow/models/taskinstance.py", line 444, in _execute_task
    result = _execute_callable(context=context, **execute_callable_kwargs)
  File "/home/airflow/.local/lib/python3.8/site-packages/airflow/models/taskinstance.py", line 414, in _execute_callable
    return execute_callable(context=context, **execute_callable_kwargs)
  File "/home/airflow/.local/lib/python3.8/site-packages/airflow/providers/http/operators/http.py", line 166, in execute
    return self.execute_sync(context=context)
  File "/home/airflow/.local/lib/python3.8/site-packages/airflow/providers/http/operators/http.py", line 170, in execute_sync
    response = self.hook.run(self.endpoint, self.data, self.headers, self.extra_options)
  File "/home/airflow/.local/lib/python3.8/site-packages/airflow/providers/http/operators/http.py", line 148, in hook
    conn = BaseHook.get_connection(conn_id)
  File "/home/airflow/.local/lib/python3.8/site-packages/airflow/hooks/base.py", line 82, in get_connection
    conn = Connection.get_connection_from_secrets(conn_id)
  File "/home/airflow/.local/lib/python3.8/site-packages/airflow/models/connection.py", line 514, in get_connection_from_secrets
    raise AirflowNotFoundException(f"The conn_id `{conn_id}` isn't defined")
airflow.exceptions.AirflowNotFoundException: The conn_id `openweathermap_api` isn't defined
[2024-07-24T01:17:14.945+0000] {taskinstance.py:1149} INFO - Marking task as UP_FOR_RETRY. dag_id=openweathermap, task_id=weather_fetch_honolulu, execution_date=20240724T011712, start_date=20240724T011714, end_date=20240724T011714
[2024-07-24T01:17:14.956+0000] {standard_task_runner.py:107} ERROR - Failed to execute job 14 for task weather_fetch_honolulu (The conn_id `openweathermap_api` isn't defined; 80)
[2024-07-24T01:17:14.968+0000] {local_task_job_runner.py:234} INFO - Task exited with return code 1
[2024-07-24T01:17:14.987+0000] {taskinstance.py:3312} INFO - 0 downstream tasks scheduled from follow-on schedule check
