[2024-07-24T01:24:51.016+0000] {taskinstance.py:1979} INFO - Dependencies all met for dep_context=non-requeueable deps ti=<TaskInstance: openweathermap.weather_fetch_honolulu manual__2024-07-24T01:17:12.470445+00:00 [queued]>
[2024-07-24T01:24:51.022+0000] {taskinstance.py:1979} INFO - Dependencies all met for dep_context=requeueable deps ti=<TaskInstance: openweathermap.weather_fetch_honolulu manual__2024-07-24T01:17:12.470445+00:00 [queued]>
[2024-07-24T01:24:51.022+0000] {taskinstance.py:2193} INFO - Starting attempt 3 of 4
[2024-07-24T01:24:51.034+0000] {taskinstance.py:2217} INFO - Executing <Task(HttpOperator): weather_fetch_honolulu> on 2024-07-24 01:17:12.470445+00:00
[2024-07-24T01:24:51.038+0000] {standard_task_runner.py:60} INFO - Started process 78 to run task
[2024-07-24T01:24:51.041+0000] {standard_task_runner.py:87} INFO - Running: ['***', 'tasks', 'run', 'openweathermap', 'weather_fetch_honolulu', 'manual__2024-07-24T01:17:12.470445+00:00', '--job-id', '23', '--raw', '--subdir', 'DAGS_FOLDER/weather_dag.py', '--cfg-path', '/tmp/tmpky0u35gp']
[2024-07-24T01:24:51.042+0000] {standard_task_runner.py:88} INFO - Job 23: Subtask weather_fetch_honolulu
[2024-07-24T01:24:51.077+0000] {task_command.py:423} INFO - Running <TaskInstance: openweathermap.weather_fetch_honolulu manual__2024-07-24T01:17:12.470445+00:00 [running]> on host a27cffbe2c0f
[2024-07-24T01:24:51.138+0000] {taskinstance.py:2513} INFO - Exporting env vars: AIRFLOW_CTX_DAG_OWNER='snowglobe' AIRFLOW_CTX_DAG_ID='openweathermap' AIRFLOW_CTX_TASK_ID='weather_fetch_honolulu' AIRFLOW_CTX_EXECUTION_DATE='2024-07-24T01:17:12.470445+00:00' AIRFLOW_CTX_TRY_NUMBER='3' AIRFLOW_CTX_DAG_RUN_ID='manual__2024-07-24T01:17:12.470445+00:00'
[2024-07-24T01:24:51.139+0000] {http.py:169} INFO - Calling HTTP method
[2024-07-24T01:24:51.151+0000] {taskinstance.py:2731} ERROR - Task failed with exception
Traceback (most recent call last):
  File "/home/airflow/.local/lib/python3.8/site-packages/airflow/models/taskinstance.py", line 444, in _execute_task
    result = _execute_callable(context=context, **execute_callable_kwargs)
  File "/home/airflow/.local/lib/python3.8/site-packages/airflow/models/taskinstance.py", line 414, in _execute_callable
    return execute_callable(context=context, **execute_callable_kwargs)
  File "/home/airflow/.local/lib/python3.8/site-packages/airflow/providers/http/operators/http.py", line 166, in execute
    return self.execute_sync(context=context)
  File "/home/airflow/.local/lib/python3.8/site-packages/airflow/providers/http/operators/http.py", line 170, in execute_sync
    response = self.hook.run(self.endpoint, self.data, self.headers, self.extra_options)
  File "/home/airflow/.local/lib/python3.8/site-packages/airflow/providers/http/operators/http.py", line 148, in hook
    conn = BaseHook.get_connection(conn_id)
  File "/home/airflow/.local/lib/python3.8/site-packages/airflow/hooks/base.py", line 82, in get_connection
    conn = Connection.get_connection_from_secrets(conn_id)
  File "/home/airflow/.local/lib/python3.8/site-packages/airflow/models/connection.py", line 514, in get_connection_from_secrets
    raise AirflowNotFoundException(f"The conn_id `{conn_id}` isn't defined")
airflow.exceptions.AirflowNotFoundException: The conn_id `openweathermap_api` isn't defined
[2024-07-24T01:24:51.153+0000] {taskinstance.py:1149} INFO - Marking task as UP_FOR_RETRY. dag_id=openweathermap, task_id=weather_fetch_honolulu, execution_date=20240724T011712, start_date=20240724T012451, end_date=20240724T012451
[2024-07-24T01:24:51.163+0000] {standard_task_runner.py:107} ERROR - Failed to execute job 23 for task weather_fetch_honolulu (The conn_id `openweathermap_api` isn't defined; 78)
[2024-07-24T01:24:51.173+0000] {local_task_job_runner.py:234} INFO - Task exited with return code 1
[2024-07-24T01:24:51.193+0000] {taskinstance.py:3312} INFO - 0 downstream tasks scheduled from follow-on schedule check
