[2024-07-27T23:23:06.202+0000] {taskinstance.py:1979} INFO - Dependencies all met for dep_context=non-requeueable deps ti=<TaskInstance: openweathermap.transform manual__2024-07-27T23:22:56.864146+00:00 [queued]>
[2024-07-27T23:23:06.208+0000] {taskinstance.py:1979} INFO - Dependencies all met for dep_context=requeueable deps ti=<TaskInstance: openweathermap.transform manual__2024-07-27T23:22:56.864146+00:00 [queued]>
[2024-07-27T23:23:06.208+0000] {taskinstance.py:2193} INFO - Starting attempt 1 of 2
[2024-07-27T23:23:06.219+0000] {taskinstance.py:2217} INFO - Executing <Task(_PythonDecoratedOperator): transform> on 2024-07-27 23:22:56.864146+00:00
[2024-07-27T23:23:06.224+0000] {standard_task_runner.py:60} INFO - Started process 169 to run task
[2024-07-27T23:23:06.226+0000] {standard_task_runner.py:87} INFO - Running: ['***', 'tasks', 'run', 'openweathermap', 'transform', 'manual__2024-07-27T23:22:56.864146+00:00', '--job-id', '158', '--raw', '--subdir', 'DAGS_FOLDER/weather_dag.py', '--cfg-path', '/tmp/tmprs_oole4']
[2024-07-27T23:23:06.227+0000] {standard_task_runner.py:88} INFO - Job 158: Subtask transform
[2024-07-27T23:23:06.266+0000] {task_command.py:423} INFO - Running <TaskInstance: openweathermap.transform manual__2024-07-27T23:22:56.864146+00:00 [running]> on host 50fd5afa7976
[2024-07-27T23:23:06.348+0000] {taskinstance.py:2513} INFO - Exporting env vars: AIRFLOW_CTX_DAG_OWNER='snowglobe' AIRFLOW_CTX_DAG_ID='openweathermap' AIRFLOW_CTX_TASK_ID='transform' AIRFLOW_CTX_EXECUTION_DATE='2024-07-27T23:22:56.864146+00:00' AIRFLOW_CTX_TRY_NUMBER='1' AIRFLOW_CTX_DAG_RUN_ID='manual__2024-07-27T23:22:56.864146+00:00'
[2024-07-27T23:23:06.349+0000] {taskinstance.py:2731} ERROR - Task failed with exception
Traceback (most recent call last):
  File "/home/airflow/.local/lib/python3.8/site-packages/airflow/models/taskinstance.py", line 444, in _execute_task
    result = _execute_callable(context=context, **execute_callable_kwargs)
  File "/home/airflow/.local/lib/python3.8/site-packages/airflow/models/taskinstance.py", line 414, in _execute_callable
    return execute_callable(context=context, **execute_callable_kwargs)
  File "/home/airflow/.local/lib/python3.8/site-packages/airflow/decorators/base.py", line 241, in execute
    return_value = super().execute(context)
  File "/home/airflow/.local/lib/python3.8/site-packages/airflow/operators/python.py", line 200, in execute
    return_value = self.execute_callable()
  File "/home/airflow/.local/lib/python3.8/site-packages/airflow/operators/python.py", line 217, in execute_callable
    return self.python_callable(*self.op_args, **self.op_kwargs)
  File "/opt/airflow/dags/weather_dag.py", line 58, in transform
    result = [
  File "/opt/airflow/dags/weather_dag.py", line 60, in <listcomp>
    'name': entry['name'],
TypeError: string indices must be integers
[2024-07-27T23:23:06.355+0000] {taskinstance.py:1149} INFO - Marking task as UP_FOR_RETRY. dag_id=openweathermap, task_id=transform, execution_date=20240727T232256, start_date=20240727T232306, end_date=20240727T232306
[2024-07-27T23:23:06.363+0000] {standard_task_runner.py:107} ERROR - Failed to execute job 158 for task transform (string indices must be integers; 169)
[2024-07-27T23:23:06.398+0000] {local_task_job_runner.py:234} INFO - Task exited with return code 1
[2024-07-27T23:23:06.417+0000] {taskinstance.py:3312} INFO - 0 downstream tasks scheduled from follow-on schedule check
