[2024-07-27T23:19:32.161+0000] {taskinstance.py:1979} INFO - Dependencies all met for dep_context=non-requeueable deps ti=<TaskInstance: openweathermap.extract__3 scheduled__2024-07-27T18:00:00+00:00 [queued]>
[2024-07-27T23:19:32.170+0000] {taskinstance.py:1979} INFO - Dependencies all met for dep_context=requeueable deps ti=<TaskInstance: openweathermap.extract__3 scheduled__2024-07-27T18:00:00+00:00 [queued]>
[2024-07-27T23:19:32.170+0000] {taskinstance.py:2193} INFO - Starting attempt 1 of 2
[2024-07-27T23:19:32.183+0000] {taskinstance.py:2217} INFO - Executing <Task(_PythonDecoratedOperator): extract__3> on 2024-07-27 18:00:00+00:00
[2024-07-27T23:19:32.189+0000] {standard_task_runner.py:60} INFO - Started process 82 to run task
[2024-07-27T23:19:32.192+0000] {standard_task_runner.py:87} INFO - Running: ['***', 'tasks', 'run', 'openweathermap', 'extract__3', 'scheduled__2024-07-27T18:00:00+00:00', '--job-id', '147', '--raw', '--subdir', 'DAGS_FOLDER/weather_dag.py', '--cfg-path', '/tmp/tmpbzrltcfb']
[2024-07-27T23:19:32.195+0000] {standard_task_runner.py:88} INFO - Job 147: Subtask extract__3
[2024-07-27T23:19:32.246+0000] {task_command.py:423} INFO - Running <TaskInstance: openweathermap.extract__3 scheduled__2024-07-27T18:00:00+00:00 [running]> on host 50fd5afa7976
[2024-07-27T23:19:32.329+0000] {taskinstance.py:2513} INFO - Exporting env vars: AIRFLOW_CTX_DAG_OWNER='snowglobe' AIRFLOW_CTX_DAG_ID='openweathermap' AIRFLOW_CTX_TASK_ID='extract__3' AIRFLOW_CTX_EXECUTION_DATE='2024-07-27T18:00:00+00:00' AIRFLOW_CTX_TRY_NUMBER='1' AIRFLOW_CTX_DAG_RUN_ID='scheduled__2024-07-27T18:00:00+00:00'
[2024-07-27T23:19:32.330+0000] {taskinstance.py:2731} ERROR - Task failed with exception
Traceback (most recent call last):
  File "/home/airflow/.local/lib/python3.8/site-packages/airflow/models/taskinstance.py", line 444, in _execute_task
    result = _execute_callable(context=context, **execute_callable_kwargs)
  File "/home/airflow/.local/lib/python3.8/site-packages/airflow/models/taskinstance.py", line 414, in _execute_callable
    return execute_callable(context=context, **execute_callable_kwargs)
  File "/home/airflow/.local/lib/python3.8/site-packages/airflow/decorators/base.py", line 241, in execute
    return_value = super().execute(context)
  File "/home/airflow/.local/lib/python3.8/site-packages/airflow/operators/python.py", line 200, in execute
    return_value = self.execute_callable()
  File "/home/airflow/.local/lib/python3.8/site-packages/airflow/operators/python.py", line 217, in execute_callable
    return self.python_callable(*self.op_args, **self.op_kwargs)
  File "/opt/airflow/dags/weather_dag.py", line 53, in extract
    return json.loads(api_results)['list']
KeyError: 'list'
[2024-07-27T23:19:32.378+0000] {taskinstance.py:1149} INFO - Marking task as UP_FOR_RETRY. dag_id=openweathermap, task_id=extract__3, execution_date=20240727T180000, start_date=20240727T231932, end_date=20240727T231932
[2024-07-27T23:19:32.391+0000] {standard_task_runner.py:107} ERROR - Failed to execute job 147 for task extract__3 ('list'; 82)
[2024-07-27T23:19:32.404+0000] {local_task_job_runner.py:234} INFO - Task exited with return code 1
[2024-07-27T23:19:32.446+0000] {taskinstance.py:3312} INFO - 0 downstream tasks scheduled from follow-on schedule check
