[2024-07-25T22:33:46.064+0000] {taskinstance.py:1979} INFO - Dependencies all met for dep_context=non-requeueable deps ti=<TaskInstance: openweathermap.send_email manual__2024-07-25T22:33:12.101145+00:00 [queued]>
[2024-07-25T22:33:46.073+0000] {taskinstance.py:1979} INFO - Dependencies all met for dep_context=requeueable deps ti=<TaskInstance: openweathermap.send_email manual__2024-07-25T22:33:12.101145+00:00 [queued]>
[2024-07-25T22:33:46.073+0000] {taskinstance.py:2193} INFO - Starting attempt 2 of 3
[2024-07-25T22:33:46.085+0000] {taskinstance.py:2217} INFO - Executing <Task(_PythonDecoratedOperator): send_email> on 2024-07-25 22:33:12.101145+00:00
[2024-07-25T22:33:46.091+0000] {standard_task_runner.py:60} INFO - Started process 350 to run task
[2024-07-25T22:33:46.093+0000] {standard_task_runner.py:87} INFO - Running: ['***', 'tasks', 'run', 'openweathermap', 'send_email', 'manual__2024-07-25T22:33:12.101145+00:00', '--job-id', '80', '--raw', '--subdir', 'DAGS_FOLDER/weather_dag.py', '--cfg-path', '/tmp/tmpnbsrr9yg']
[2024-07-25T22:33:46.094+0000] {standard_task_runner.py:88} INFO - Job 80: Subtask send_email
[2024-07-25T22:33:46.132+0000] {task_command.py:423} INFO - Running <TaskInstance: openweathermap.send_email manual__2024-07-25T22:33:12.101145+00:00 [running]> on host 528d4c21eff6
[2024-07-25T22:33:46.209+0000] {taskinstance.py:2513} INFO - Exporting env vars: AIRFLOW_CTX_DAG_OWNER='snowglobe' AIRFLOW_CTX_DAG_ID='openweathermap' AIRFLOW_CTX_TASK_ID='send_email' AIRFLOW_CTX_EXECUTION_DATE='2024-07-25T22:33:12.101145+00:00' AIRFLOW_CTX_TRY_NUMBER='2' AIRFLOW_CTX_DAG_RUN_ID='manual__2024-07-25T22:33:12.101145+00:00'
[2024-07-25T22:33:46.219+0000] {warnings.py:109} WARNING - /home/***/.local/lib/python3.8/site-packages/***/utils/email.py:154: RemovedInAirflow3Warning: Fetching SMTP credentials from configuration variables will be deprecated in a future release. Please set credentials using a connection instead.
  send_mime_email(e_from=mail_from, e_to=recipients, mime_msg=msg, conn_id=conn_id, dryrun=dryrun)

[2024-07-25T22:33:46.219+0000] {email.py:270} INFO - Email alerting: attempt 1
[2024-07-25T22:33:46.583+0000] {taskinstance.py:2731} ERROR - Task failed with exception
Traceback (most recent call last):
  File "/home/airflow/.local/lib/python3.8/site-packages/airflow/models/taskinstance.py", line 444, in _execute_task
    result = _execute_callable(context=context, **execute_callable_kwargs)
  File "/home/airflow/.local/lib/python3.8/site-packages/airflow/models/taskinstance.py", line 414, in _execute_callable
    return execute_callable(context=context, **execute_callable_kwargs)
  File "/home/airflow/.local/lib/python3.8/site-packages/airflow/decorators/base.py", line 241, in execute
    return_value = super().execute(context)
  File "/home/airflow/.local/lib/python3.8/site-packages/airflow/operators/python.py", line 200, in execute
    return_value = self.execute_callable()
  File "/home/airflow/.local/lib/python3.8/site-packages/airflow/operators/python.py", line 217, in execute_callable
    return self.python_callable(*self.op_args, **self.op_kwargs)
  File "/opt/airflow/dags/weather_dag.py", line 86, in send_email
    email.execute(context=None)
  File "/home/airflow/.local/lib/python3.8/site-packages/airflow/operators/email.py", line 79, in execute
    send_email(
  File "/home/airflow/.local/lib/python3.8/site-packages/airflow/utils/email.py", line 80, in send_email
    return backend(
  File "/home/airflow/.local/lib/python3.8/site-packages/airflow/utils/email.py", line 154, in send_email_smtp
    send_mime_email(e_from=mail_from, e_to=recipients, mime_msg=msg, conn_id=conn_id, dryrun=dryrun)
  File "/home/airflow/.local/lib/python3.8/site-packages/airflow/utils/email.py", line 280, in send_mime_email
    smtp_conn.login(smtp_user, smtp_password)
  File "/usr/local/lib/python3.8/smtplib.py", line 748, in login
    raise last_exception
  File "/usr/local/lib/python3.8/smtplib.py", line 737, in login
    (code, resp) = self.auth(
  File "/usr/local/lib/python3.8/smtplib.py", line 660, in auth
    raise SMTPAuthenticationError(code, resp)
smtplib.SMTPAuthenticationError: (535, b'5.7.8 Username and Password not accepted. For more information, go to\n5.7.8  https://support.google.com/mail/?p=BadCredentials d2e1a72fcca58-70ead8288easm1589341b3a.128 - gsmtp')
[2024-07-25T22:33:46.591+0000] {taskinstance.py:1149} INFO - Marking task as UP_FOR_RETRY. dag_id=openweathermap, task_id=send_email, execution_date=20240725T223312, start_date=20240725T223346, end_date=20240725T223346
[2024-07-25T22:33:46.602+0000] {standard_task_runner.py:107} ERROR - Failed to execute job 80 for task send_email ((535, b'5.7.8 Username and Password not accepted. For more information, go to\n5.7.8  https://support.google.com/mail/?p=BadCredentials d2e1a72fcca58-70ead8288easm1589341b3a.128 - gsmtp'); 350)
[2024-07-25T22:33:46.626+0000] {local_task_job_runner.py:234} INFO - Task exited with return code 1
[2024-07-25T22:33:46.642+0000] {taskinstance.py:3312} INFO - 0 downstream tasks scheduled from follow-on schedule check
