[2024-07-25T22:32:14.485+0000] {taskinstance.py:1979} INFO - Dependencies all met for dep_context=non-requeueable deps ti=<TaskInstance: openweathermap.send_email manual__2024-07-25T22:31:35.152203+00:00 [queued]>
[2024-07-25T22:32:14.491+0000] {taskinstance.py:1979} INFO - Dependencies all met for dep_context=requeueable deps ti=<TaskInstance: openweathermap.send_email manual__2024-07-25T22:31:35.152203+00:00 [queued]>
[2024-07-25T22:32:14.491+0000] {taskinstance.py:2193} INFO - Starting attempt 2 of 3
[2024-07-25T22:32:14.501+0000] {taskinstance.py:2217} INFO - Executing <Task(_PythonDecoratedOperator): send_email> on 2024-07-25 22:31:35.152203+00:00
[2024-07-25T22:32:14.505+0000] {standard_task_runner.py:60} INFO - Started process 302 to run task
[2024-07-25T22:32:14.508+0000] {standard_task_runner.py:87} INFO - Running: ['***', 'tasks', 'run', 'openweathermap', 'send_email', 'manual__2024-07-25T22:31:35.152203+00:00', '--job-id', '72', '--raw', '--subdir', 'DAGS_FOLDER/weather_dag.py', '--cfg-path', '/tmp/tmpkyccgalw']
[2024-07-25T22:32:14.510+0000] {standard_task_runner.py:88} INFO - Job 72: Subtask send_email
[2024-07-25T22:32:14.546+0000] {task_command.py:423} INFO - Running <TaskInstance: openweathermap.send_email manual__2024-07-25T22:31:35.152203+00:00 [running]> on host 528d4c21eff6
[2024-07-25T22:32:14.614+0000] {taskinstance.py:2513} INFO - Exporting env vars: AIRFLOW_CTX_DAG_OWNER='snowglobe' AIRFLOW_CTX_DAG_ID='openweathermap' AIRFLOW_CTX_TASK_ID='send_email' AIRFLOW_CTX_EXECUTION_DATE='2024-07-25T22:31:35.152203+00:00' AIRFLOW_CTX_TRY_NUMBER='2' AIRFLOW_CTX_DAG_RUN_ID='manual__2024-07-25T22:31:35.152203+00:00'
[2024-07-25T22:32:14.617+0000] {taskinstance.py:2731} ERROR - Task failed with exception
Traceback (most recent call last):
  File "/home/airflow/.local/lib/python3.8/site-packages/airflow/models/taskinstance.py", line 444, in _execute_task
    result = _execute_callable(context=context, **execute_callable_kwargs)
  File "/home/airflow/.local/lib/python3.8/site-packages/airflow/models/taskinstance.py", line 414, in _execute_callable
    return execute_callable(context=context, **execute_callable_kwargs)
  File "/home/airflow/.local/lib/python3.8/site-packages/airflow/decorators/base.py", line 241, in execute
    return_value = super().execute(context)
  File "/home/airflow/.local/lib/python3.8/site-packages/airflow/operators/python.py", line 200, in execute
    return_value = self.execute_callable()
  File "/home/airflow/.local/lib/python3.8/site-packages/airflow/operators/python.py", line 217, in execute_callable
    return self.python_callable(*self.op_args, **self.op_kwargs)
  File "/opt/airflow/dags/weather_dag.py", line 86, in send_email
    email.execute(context=None)
  File "/home/airflow/.local/lib/python3.8/site-packages/airflow/operators/email.py", line 79, in execute
    send_email(
  File "/home/airflow/.local/lib/python3.8/site-packages/airflow/utils/email.py", line 80, in send_email
    return backend(
  File "/home/airflow/.local/lib/python3.8/site-packages/airflow/utils/email.py", line 141, in send_email_smtp
    msg, recipients = build_mime_message(
  File "/home/airflow/.local/lib/python3.8/site-packages/airflow/utils/email.py", line 208, in build_mime_message
    with open(fname, "rb") as file:
FileNotFoundError: [Errno 2] No such file or directory: '/output.csv'
[2024-07-25T22:32:14.623+0000] {taskinstance.py:1149} INFO - Marking task as UP_FOR_RETRY. dag_id=openweathermap, task_id=send_email, execution_date=20240725T223135, start_date=20240725T223214, end_date=20240725T223214
[2024-07-25T22:32:14.633+0000] {standard_task_runner.py:107} ERROR - Failed to execute job 72 for task send_email ([Errno 2] No such file or directory: '/output.csv'; 302)
[2024-07-25T22:32:14.680+0000] {local_task_job_runner.py:234} INFO - Task exited with return code 1
[2024-07-25T22:32:14.694+0000] {taskinstance.py:3312} INFO - 0 downstream tasks scheduled from follow-on schedule check
