[2024-07-26T22:38:39.626+0000] {taskinstance.py:1979} INFO - Dependencies all met for dep_context=non-requeueable deps ti=<TaskInstance: openweathermap.weather_fetch_honolulu manual__2024-07-26T22:38:37.660148+00:00 [queued]>
[2024-07-26T22:38:39.633+0000] {taskinstance.py:1979} INFO - Dependencies all met for dep_context=requeueable deps ti=<TaskInstance: openweathermap.weather_fetch_honolulu manual__2024-07-26T22:38:37.660148+00:00 [queued]>
[2024-07-26T22:38:39.633+0000] {taskinstance.py:2193} INFO - Starting attempt 1 of 2
[2024-07-26T22:38:39.647+0000] {taskinstance.py:2217} INFO - Executing <Task(HttpOperator): weather_fetch_honolulu> on 2024-07-26 22:38:37.660148+00:00
[2024-07-26T22:38:39.652+0000] {standard_task_runner.py:60} INFO - Started process 703 to run task
[2024-07-26T22:38:39.655+0000] {standard_task_runner.py:87} INFO - Running: ['***', 'tasks', 'run', 'openweathermap', 'weather_fetch_honolulu', 'manual__2024-07-26T22:38:37.660148+00:00', '--job-id', '119', '--raw', '--subdir', 'DAGS_FOLDER/weather_dag.py', '--cfg-path', '/tmp/tmpbm5szp4b']
[2024-07-26T22:38:39.657+0000] {standard_task_runner.py:88} INFO - Job 119: Subtask weather_fetch_honolulu
[2024-07-26T22:38:39.706+0000] {task_command.py:423} INFO - Running <TaskInstance: openweathermap.weather_fetch_honolulu manual__2024-07-26T22:38:37.660148+00:00 [running]> on host 4f85b8e02846
[2024-07-26T22:38:39.780+0000] {taskinstance.py:2513} INFO - Exporting env vars: AIRFLOW_CTX_DAG_OWNER='snowglobe' AIRFLOW_CTX_DAG_ID='openweathermap' AIRFLOW_CTX_TASK_ID='weather_fetch_honolulu' AIRFLOW_CTX_EXECUTION_DATE='2024-07-26T22:38:37.660148+00:00' AIRFLOW_CTX_TRY_NUMBER='1' AIRFLOW_CTX_DAG_RUN_ID='manual__2024-07-26T22:38:37.660148+00:00'
[2024-07-26T22:38:39.781+0000] {http.py:169} INFO - Calling HTTP method
[2024-07-26T22:38:39.789+0000] {base.py:83} INFO - Using connection ID 'openweathermap_api' for task execution.
[2024-07-26T22:38:39.795+0000] {base.py:83} INFO - Using connection ID 'openweathermap_api' for task execution.
[2024-07-26T22:38:39.874+0000] {http.py:199} ERROR - HTTP error: Not Found
[2024-07-26T22:38:39.874+0000] {http.py:200} ERROR - {"cod":"404","message":"Internal error"}
[2024-07-26T22:38:39.883+0000] {taskinstance.py:2731} ERROR - Task failed with exception
Traceback (most recent call last):
  File "/home/airflow/.local/lib/python3.8/site-packages/airflow/providers/http/hooks/http.py", line 197, in check_response
    response.raise_for_status()
  File "/home/airflow/.local/lib/python3.8/site-packages/requests/models.py", line 1021, in raise_for_status
    raise HTTPError(http_error_msg, response=self)
requests.exceptions.HTTPError: 404 Client Error: Not Found for url: https://api.openweathermap.org/data/2.5/weather/data/2.5/forecast?lat=21.315603&lon=-157.858093&appid=***&units=metric

During handling of the above exception, another exception occurred:

Traceback (most recent call last):
  File "/home/airflow/.local/lib/python3.8/site-packages/airflow/models/taskinstance.py", line 444, in _execute_task
    result = _execute_callable(context=context, **execute_callable_kwargs)
  File "/home/airflow/.local/lib/python3.8/site-packages/airflow/models/taskinstance.py", line 414, in _execute_callable
    return execute_callable(context=context, **execute_callable_kwargs)
  File "/home/airflow/.local/lib/python3.8/site-packages/airflow/providers/http/operators/http.py", line 166, in execute
    return self.execute_sync(context=context)
  File "/home/airflow/.local/lib/python3.8/site-packages/airflow/providers/http/operators/http.py", line 170, in execute_sync
    response = self.hook.run(self.endpoint, self.data, self.headers, self.extra_options)
  File "/home/airflow/.local/lib/python3.8/site-packages/airflow/providers/http/hooks/http.py", line 187, in run
    return self.run_and_check(session, prepped_request, extra_options)
  File "/home/airflow/.local/lib/python3.8/site-packages/airflow/providers/http/hooks/http.py", line 238, in run_and_check
    self.check_response(response)
  File "/home/airflow/.local/lib/python3.8/site-packages/airflow/providers/http/hooks/http.py", line 201, in check_response
    raise AirflowException(str(response.status_code) + ":" + response.reason)
airflow.exceptions.AirflowException: 404:Not Found
[2024-07-26T22:38:39.886+0000] {taskinstance.py:1149} INFO - Marking task as UP_FOR_RETRY. dag_id=openweathermap, task_id=weather_fetch_honolulu, execution_date=20240726T223837, start_date=20240726T223839, end_date=20240726T223839
[2024-07-26T22:38:39.909+0000] {standard_task_runner.py:107} ERROR - Failed to execute job 119 for task weather_fetch_honolulu (404:Not Found; 703)
[2024-07-26T22:38:39.947+0000] {local_task_job_runner.py:234} INFO - Task exited with return code 1
[2024-07-26T22:38:39.972+0000] {taskinstance.py:3312} INFO - 0 downstream tasks scheduled from follow-on schedule check
